<?xml version="1.0" ?>
<sdf version="1.9">
    <world name="car_world">
        <plugin filename="ignition-gazebo-physics-system"
            name="ignition::gazebo::systems::Physics">
        </plugin>
        <plugin filename="ignition-gazebo-scene-broadcaster-system"
            name="ignition::gazebo::systems::SceneBroadcaster">
        </plugin>
        <plugin filename="libignition-gazebo-imu-system.so"
                name="ignition::gazebo::systems::Imu">
        </plugin>
        <plugin filename="libignition-gazebo-contact-system.so"
                name="ignition::gazebo::systems::Contact">
        </plugin>
        <plugin filename="libignition-gazebo-sensors-system.so"
          name="ignition::gazebo::systems::Sensors">
          <render_engine>ogre2</render_engine>
        </plugin>


        <physics name="10ms" type="ignored">
            <max_step_size>0.01</max_step_size>
            <real_time_factor>1.0</real_time_factor>
        </physics>

        <light type="directional" name="sun">
            <cast_shadows>true</cast_shadows>
            <pose>0 0 10 0 0 0</pose>
            <diffuse>0.8 0.8 0.8 1</diffuse>
            <specular>0.2 0.2 0.2 1</specular>
            <attenuation>
                <range>1000</range>
                <constant>0.9</constant>
                <linear>0.01</linear>
                <quadratic>0.001</quadratic>
            </attenuation>
            <direction>-0.5 0.1 -0.9</direction>
        </light>

        <model name="f110_car" canonical_link="chassis">
            <frame name="lidar_frame" attached_to='chassis'>
                <pose>0.8 0 0.5 0 0 0</pose>
            </frame>
            <pose relative_to="world">0 2 0.325 0 0 0</pose> <!-- X Y Z R P Y first three are position, last three are orientation in roll, pitch and yaw-->

            <link name='chassis'>
                <pose>-0.2 -0 0.2 0 -0 0</pose>
                <inertial>
                    <mass>1.14395</mass>
                    <inertia>
                        <ixx>0.126164</ixx>
                        <ixy>0</ixy>
                        <ixz>0</ixz>
                        <iyy>0.416519</iyy>
                        <iyz>0</iyz>
                        <izz>0.481014</izz>
                    </inertia>
                </inertial>
                <visual name='visual'>
                    <geometry>
                        <box>
                            <size>2 1 0.5</size>
                        </box>
                    </geometry>
                    <material>
                        <ambient>0.5 0.5 1.0 1</ambient>
                        <diffuse>0.5 0.5 1.0 1</diffuse>
                        <specular>0.0 0.0 1.0 1</specular>
                    </material>
                </visual>
                <collision name='collision'>
                    <geometry>
                        <box>
                            <size>2.01142 1 0.568726</size>
                        </box>
                    </geometry>
                </collision>
            </link>

            <link name='front_left_wheel'>
                <pose>0.554283 0.625029 -0.025 -1.5707 0 0</pose>
                <inertial>
                    <mass>2</mass>
                    <inertia>
                        <ixx>0.145833</ixx>
                        <ixy>0</ixy>
                        <ixz>0</ixz>
                        <iyy>0.145833</iyy>
                        <iyz>0</iyz>
                        <izz>0.125</izz>
                    </inertia>
                </inertial>
                <visual name='visual'>
                    <geometry>
                        <cylinder>
                            <length>0.15</length>
                            <radius>0.3</radius>
                        </cylinder>
                    </geometry>
                    <material>
                        <ambient>0.2 0.2 0.2 1</ambient>
                        <diffuse>0.2 0.2 0.2 1</diffuse>
                        <specular>0.2 0.2 0.2 1</specular>
                    </material>
                </visual>
                <collision name='collision'>
                    <geometry>
                        <cylinder>
                            <length>0.15</length>
                            <radius>0.3</radius>
                        </cylinder>
                    </geometry>
                    <surface>
                        <friction>
                            <ode>
                                <mu>0.5</mu>
                                <mu2>1.0</mu2>
                                <fdir1>0 0 1</fdir1>
                            </ode>
                            <bullet>
                                <friction>0.5</friction>
                                <friction2>1</friction2>
                                <rolling_friction>0.1</rolling_friction>
                            </bullet>
                        </friction>
                    </surface>
                </collision>
            </link>

            <link name='rear_left_wheel'>
                <pose>-0.957138 0.625029 -0.025 -1.5707 0 0</pose>
                <inertial>
                    <mass>2</mass>
                    <inertia>
                        <ixx>0.145833</ixx>
                        <ixy>0</ixy>
                        <ixz>0</ixz>
                        <iyy>0.145833</iyy>
                        <iyz>0</iyz>
                        <izz>0.125</izz>
                    </inertia>
                </inertial>
                <visual name='visual'>
                    <geometry>
                        <cylinder>
                            <length>0.15</length>
                            <radius>0.3</radius>
                        </cylinder>
                    </geometry>
                    <material>
                        <ambient>0.2 0.2 0.2 1</ambient>
                        <diffuse>0.2 0.2 0.2 1</diffuse>
                        <specular>0.2 0.2 0.2 1</specular>
                    </material>
                </visual>
                <collision name='collision'>
                    <geometry>
                        <cylinder>
                            <length>0.15</length>
                            <radius>0.3</radius>
                        </cylinder>
                    </geometry>
                    <surface>
                        <friction>
                            <ode>
                                <mu>0.5</mu>
                                <mu2>1.0</mu2>
                                <fdir1>0 0 1</fdir1>
                            </ode>
                            <bullet>
                                <friction>0.5</friction>
                                <friction2>1</friction2>
                                <rolling_friction>0.5</rolling_friction>
                            </bullet>
                        </friction>
                    </surface>
                </collision>
            </link>

            <link name='front_right_wheel'>
                <pose>0.554282 -0.625029 -0.025 -1.5707 0 0</pose>
                <inertial>
                    <mass>2</mass>
                    <inertia>
                        <ixx>0.145833</ixx>
                        <ixy>0</ixy>
                        <ixz>0</ixz>
                        <iyy>0.145833</iyy>
                        <iyz>0</iyz>
                        <izz>0.125</izz>
                    </inertia>
                </inertial>
                <visual name='visual'>
                    <geometry>
                        <cylinder>
                            <length>0.15</length>
                            <radius>0.3</radius>
                        </cylinder>
                    </geometry>
                    <material>
                        <ambient>0.2 0.2 0.2 1</ambient>
                        <diffuse>0.2 0.2 0.2 1</diffuse>
                        <specular>0.2 0.2 0.2 1</specular>
                    </material>
                </visual>
                <collision name='collision'>
                    <geometry>
                        <cylinder>
                            <length>0.15</length>
                            <radius>0.3</radius>
                        </cylinder>
                    </geometry>
                    <surface>
                        <friction>
                            <ode>
                                <mu>0.5</mu>
                                <mu2>1.0</mu2>
                                <fdir1>0 0 1</fdir1>
                            </ode>
                            <bullet>
                                <friction>0.5</friction>
                                <friction2>1</friction2>
                                <rolling_friction>0.1</rolling_friction>
                            </bullet>
                        </friction>
                    </surface>
                </collision>
            </link>

            <link name='rear_right_wheel'>
                <pose>-0.957138 -0.625029 -0.025 -1.5707 0 0</pose>
                <inertial>
                    <mass>2</mass>
                    <inertia>
                        <ixx>0.145833</ixx>
                        <ixy>0</ixy>
                        <ixz>0</ixz>
                        <iyy>0.145833</iyy>
                        <iyz>0</iyz>
                        <izz>0.125</izz>
                    </inertia>
                </inertial>
                <visual name='visual'>
                    <geometry>
                        <cylinder>
                            <length>0.15</length>
                            <radius>0.3</radius>
                        </cylinder>
                    </geometry>
                    <material>
                        <ambient>0.2 0.2 0.2 1</ambient>
                        <diffuse>0.2 0.2 0.2 1</diffuse>
                        <specular>0.2 0.2 0.2 1</specular>
                    </material>
                </visual>
                <collision name='collision'>
                    <geometry>
                        <cylinder>
                            <length>0.15</length>
                            <radius>0.3</radius>
                        </cylinder>
                    </geometry>
                    <surface>
                        <friction>
                            <ode>
                                <mu>0.5</mu>
                                <mu2>1.0</mu2>
                                <fdir1>0 0 1</fdir1>
                            </ode>
                            <bullet>
                                <friction>0.5</friction>
                                <friction2>1</friction2>
                                <rolling_friction>0.5</rolling_friction>
                            </bullet>
                        </friction>
                    </surface>
                </collision>
            </link>

            <link name="front_left_wheel_steering_link">
                <pose>0.554283 0.5 0.02 0 0 0</pose>
                <inertial>
                    <mass>0.5</mass>
                    <inertia>
                        <ixx>0.0153</ixx>
                        <iyy>0.025</iyy>
                        <izz>0.0153</izz>
                    </inertia>
                </inertial>
                <visual name="steering_link_visual">
                    <pose>0 0 0 0 0 0</pose>
                    <geometry>
                        <cylinder>
                            <length>0.1</length>
                            <radius>0.03</radius>
                        </cylinder>
                    </geometry>
                    <material>
                        <ambient>1 1 1</ambient>
                        <diffuse>1 1 1</diffuse>
                    </material>
                </visual>
            </link>

            <link name="front_right_wheel_steering_link">
                <pose>0.554283 -0.5 0.02 0 0 0</pose>
                <inertial>
                    <mass>0.5</mass>
                    <inertia>
                        <ixx>0.0153</ixx>
                        <iyy>0.025</iyy>
                        <izz>0.0153</izz>
                    </inertia>
                </inertial>
                <visual name="steering_link_visual">
                    <pose>0 0 0 0 0 0</pose>
                    <geometry>
                        <cylinder>
                            <length>0.1</length>
                            <radius>0.03</radius>
                        </cylinder>
                    </geometry>
                    <material>
                        <ambient>1 1 1</ambient>
                        <diffuse>1 1 1</diffuse>
                    </material>
                </visual>
            </link>

            <joint name="front_left_wheel_steering_joint" type="revolute">
                <child>front_left_wheel_steering_link</child>
                <parent>chassis</parent>
                <axis>
                    <xyz>0 0 1</xyz>
                    <limit>
                        <lower>-0.6</lower>
                        <upper>+0.6</upper>
                        <velocity>1.0</velocity>
                        <effort>25</effort>
                    </limit>
                    <use_parent_model_frame>1</use_parent_model_frame>
                </axis>
            </joint>

            <joint name="front_right_wheel_steering_joint" type="revolute">
                <parent>chassis</parent>
                <child>front_right_wheel_steering_link</child>
                <axis>
                    <xyz>0 0 1</xyz>
                    <limit>
                        <lower>-0.6</lower>
                        <upper>+0.6</upper>
                        <velocity>1.0</velocity>
                        <effort>25</effort>
                    </limit>
                </axis>
            </joint>

            <joint name='front_left_wheel_joint' type='revolute'>
                <parent>front_left_wheel_steering_link</parent>
                <child>front_left_wheel</child>
                <axis>
                    <xyz>0 0 1</xyz>
                    <limit>
                        <lower>-1.79769e+308</lower>
                        <upper>1.79769e+308</upper>
                    </limit>
                </axis>
            </joint>

            <joint name='front_right_wheel_joint' type='revolute'>
                <parent>front_right_wheel_steering_link</parent>
                <child>front_right_wheel</child>
                <axis>
                    <xyz>0 0 1</xyz>
                    <limit>
                        <lower>-1.79769e+308</lower>
                        <upper>1.79769e+308</upper>
                    </limit>
                </axis>
            </joint>

            <joint name='rear_left_wheel_joint' type='revolute'>
                <parent>chassis</parent>
                <child>rear_left_wheel</child>
                <axis>
                    <xyz>0 0 1</xyz>
                    <limit>
                        <lower>-1.79769e+308</lower>
                        <upper>1.79769e+308</upper>
                    </limit>
                </axis>
            </joint>

            <joint name='rear_right_wheel_joint' type='revolute'>
                <parent>chassis</parent>
                <child>rear_right_wheel</child>
                <axis>
                    <xyz>0 0 1</xyz>
                    <limit>
                        <lower>-1.79769e+308</lower>
                        <upper>1.79769e+308</upper>
                    </limit>
                </axis>
            </joint>
            <!-- SENSORS -->
            <link name="camera_link">
                <pose>0.7 0 0.5 0 0 0</pose>
                <inertial>
                    <mass>0.1</mass>
                    <inertia>
                        <ixx>0.000166667</ixx>
                        <iyy>0.000166667</iyy>
                        <izz>0.000166667</izz>
                    </inertia>
                </inertial>
                <collision name="collision">
                    <geometry>
                        <box>
                            <size>0.1 0.1 0.1</size>
                        </box>
                    </geometry>
                </collision>
                <visual name="visual">
                    <geometry>
                        <box>
                            <size>0.1 0.1 0.1</size>
                        </box>
                    </geometry>
                </visual>

                <sensor name="camera" type="camera">
                    <camera>
                        <horizontal_fov>1.047</horizontal_fov>
                        <image>
                            <width>320</width>
                            <height>240</height>
                        </image>
                        <clip>
                            <near>0.1</near>
                            <far>100</far>
                        </clip>
                    </camera>
                    <always_on>1</always_on>
                    <update_rate>30</update_rate>
                    <visualize>true</visualize>
                    <topic>camera</topic>
                </sensor>
            </link>

            <link name="lidar_link">
                <pose>0 0 0.6 0 0 0</pose>
                <inertial>
                    <mass>0.1</mass>
                    <inertia>
                        <ixx>0.000166667</ixx>
                        <iyy>0.000166667</iyy>
                        <izz>0.000166667</izz>
                    </inertia>
                </inertial>
                <collision name="collision">
                    <geometry>
                        <box>
                            <size>0.1 0.1 0.1</size>
                        </box>
                    </geometry>
                </collision>
                <visual name="visual">
                    <geometry>
                        <box>
                            <size>0.1 0.1 0.1</size>
                        </box>
                    </geometry>
                </visual>
                <sensor name='gpu_lidar' type='gpu_lidar'>"
                <topic>scan</topic>
                <update_rate>10</update_rate>
                <ray>
                    <scan>
                        <horizontal>
                            <samples>640</samples>
                            <resolution>1</resolution>
                            <min_angle>-1.396263</min_angle>
                            <max_angle>1.396263</max_angle>
                        </horizontal>
                        <vertical>
                            <samples>1</samples>
                            <resolution>0.01</resolution>
                            <min_angle>0</min_angle>
                            <max_angle>0</max_angle>
                        </vertical>
                    </scan>
                    <range>
                        <min>0.08</min>
                        <max>10.0</max>
                        <resolution>0.01</resolution>
                    </range>
                </ray>
                <always_on>1</always_on>
                <visualize>true</visualize>
            </sensor>
        </link>

        <joint name="camera_joint" type="fixed">
            <parent>chassis</parent>
            <child>camera_link</child>
        </joint>
        <joint name="lidar_joint" type="fixed">
            <parent>chassis</parent>
            <child>lidar_link</child>
        </joint>

        <plugin
            filename="gz-sim-ackermann-steering-system"
            name="gz::sim::systems::AckermannSteering">
            <topic>cmd_vel</topic>
            <left_joint>front_left_wheel_joint</left_joint>
            <left_joint>rear_left_wheel_joint</left_joint>
            <right_joint>front_right_wheel_joint</right_joint>
            <right_joint>rear_right_wheel_joint</right_joint>
            <left_steering_joint>front_left_wheel_steering_joint</left_steering_joint>
            <right_steering_joint>front_right_wheel_steering_joint</right_steering_joint>
            <kingpin_width>1.0</kingpin_width>
            <!--steering_limit>0.5</steering_limit-->
            <wheel_base>1.0</wheel_base>
            <wheel_separation>1.25</wheel_separation>
            <wheel_radius>0.3</wheel_radius>
            <!--min_velocity>-1</min_velocity-->
            <!--max_velocity>1</max_velocity-->
            <min_acceleration>-3</min_acceleration>
            <max_acceleration>3</max_acceleration>
        </plugin>
            </model>


            <model name="ground_plane">
                <static>true</static>
                <link name="link">
                    <collision name="collision">
                        <geometry>
                            <plane>
                                <normal>0 0 1</normal>
                            </plane>
                </geometry>
                </collision>
                <visual name="visual">
                <geometry>
                    <plane>
                    <normal>0 0 1</normal>
                    <size>100 100</size>
                    </plane>
                </geometry>
                <material>
                    <ambient>0.8 0.8 0.8 1</ambient>
                    <diffuse>0.8 0.8 0.8 1</diffuse>
                    <specular>0.8 0.8 0.8 1</specular>
                </material>
                </visual>
            </link>
        </model>
    </world>
</sdf>
