<?xml version="1.0" ?>
<sdf version="1.9">
    <model name="f110_car" canonical_link="chassis">
        <frame name="lidar_frame" attached_to='chassis'>
            <pose>0.8 0 0.5 0 0 0</pose>
        </frame>

        <link name='chassis'>
            <pose>-0.27 0.085 0.05 0 0 0</pose>
            <inertial>
                <mass>1.14395</mass>
                <inertia>
                    <ixx>0.126164</ixx>
                    <ixy>0</ixy>
                    <ixz>0</ixz>
                    <iyy>0.416519</iyy>
                    <iyz>0</iyz>
                    <izz>0.481014</izz>
                </inertia>
            </inertial>
            <visual name='visual'>
                <geometry>
                    <box>
                        <size>0.54 0.17 0.08</size>
                    </box>
                </geometry>
                <material>
                    <ambient>0.5 0.5 1.0 1</ambient>
                    <diffuse>0.5 0.5 1.0 1</diffuse>
                    <specular>0.0 0.0 1.0 1</specular>
                </material>
            </visual>
            <collision name='collision'>
                <geometry>
                    <box>
                        <size>0.54 0.17 0.08</size>
                    </box>
                </geometry>
            </collision>
            <sensor name="imu_sensor" type="imu">
                <always_on>1</always_on>
                <update_rate>1</update_rate>
                <visualize>true</visualize>
                <topic>imu</topic>
            </sensor>
        </link>

        <link name='front_left_wheel'>
            <pose relative_to="chassis">0.11 0.15 -0.05 -1.5707 0 0</pose>
            <inertial>
                <mass>2</mass>
                <inertia>
                    <ixx>0.145833</ixx>
                    <ixy>0</ixy>
                    <ixz>0</ixz>
                    <iyy>0.145833</iyy>
                    <iyz>0</iyz>
                    <izz>0.125</izz>
                </inertia>
            </inertial>
            <visual name='visual'>
                <geometry>
                    <cylinder>
                        <length>0.04</length>
                        <radius>0.055</radius>
                    </cylinder>
                </geometry>
                <material>
                    <ambient>0.2 0.2 0.2 1</ambient>
                    <diffuse>0.2 0.2 0.2 1</diffuse>
                    <specular>0.2 0.2 0.2 1</specular>
                </material>
            </visual>
            <collision name='collision'>
                <geometry>
                    <cylinder>
                        <length>0.04</length>
                        <radius>0.055</radius>
                    </cylinder>
                </geometry>
                <surface>
                    <friction>
                        <ode>
                            <mu>0.5</mu>
                            <mu2>1.0</mu2>
                            <fdir1>0 0 1</fdir1>
                        </ode>
                        <bullet>
                            <friction>0.5</friction>
                            <friction2>1</friction2>
                            <rolling_friction>0.1</rolling_friction>
                        </bullet>
                    </friction>
                </surface>
            </collision>
        </link>

        <link name='rear_left_wheel'>
            <pose relative_to="chassis">-0.11 0.15 -0.05 -1.5707 0 0</pose>
            <inertial>
                <mass>2</mass>
                <inertia>
                    <ixx>0.145833</ixx>
                    <ixy>0</ixy>
                    <ixz>0</ixz>
                    <iyy>0.145833</iyy>
                    <iyz>0</iyz>
                    <izz>0.125</izz>
                </inertia>
            </inertial>
            <visual name='visual'>
                <geometry>
                    <cylinder>
                        <length>0.04</length>
                        <radius>0.055</radius>
                    </cylinder>
                </geometry>
                <material>
                    <ambient>0.2 0.2 0.2 1</ambient>
                    <diffuse>0.2 0.2 0.2 1</diffuse>
                    <specular>0.2 0.2 0.2 1</specular>
                </material>
            </visual>
            <collision name='collision'>
                <geometry>
                    <cylinder>
                        <length>0.04</length>
                        <radius>0.055</radius>
                    </cylinder>
                </geometry>
                <surface>
                    <friction>
                        <ode>
                            <mu>0.5</mu>
                            <mu2>1.0</mu2>
                            <fdir1>0 0 1</fdir1>
                        </ode>
                        <bullet>
                            <friction>0.5</friction>
                            <friction2>1</friction2>
                            <rolling_friction>0.5</rolling_friction>
                        </bullet>
                    </friction>
                </surface>
            </collision>
        </link>

        <link name='front_right_wheel'>
            <pose relative_to="chassis">0.11 -0.15 -0.05 -1.5707 0 0</pose>
            <inertial>
                <mass>2</mass>
                <inertia>
                    <ixx>0.145833</ixx>
                    <ixy>0</ixy>
                    <ixz>0</ixz>
                    <iyy>0.145833</iyy>
                    <iyz>0</iyz>
                    <izz>0.125</izz>
                </inertia>
            </inertial>
            <visual name='visual'>
                <geometry>
                    <cylinder>
                        <length>0.04</length>
                        <radius>0.055</radius>
                    </cylinder>
                </geometry>
                <material>
                    <ambient>0.2 0.2 0.2 1</ambient>
                    <diffuse>0.2 0.2 0.2 1</diffuse>
                    <specular>0.2 0.2 0.2 1</specular>
                </material>
            </visual>
            <collision name='collision'>
                <geometry>
                    <cylinder>
                        <length>0.04</length>
                        <radius>0.055</radius>
                    </cylinder>
                </geometry>
                <surface>
                    <friction>
                        <ode>
                            <mu>0.5</mu>
                            <mu2>1.0</mu2>
                            <fdir1>0 0 1</fdir1>
                        </ode>
                        <bullet>
                            <friction>0.5</friction>
                            <friction2>1</friction2>
                            <rolling_friction>0.1</rolling_friction>
                        </bullet>
                    </friction>
                </surface>
            </collision>
        </link>

        <link name='rear_right_wheel'>
            <pose relative_to="chassis">-0.11 -0.15 -0.05 -1.5707 0 0</pose>
            <inertial>
                <mass>2</mass>
                <inertia>
                    <ixx>0.145833</ixx>
                    <ixy>0</ixy>
                    <ixz>0</ixz>
                    <iyy>0.145833</iyy>
                    <iyz>0</iyz>
                    <izz>0.125</izz>
                </inertia>
            </inertial>
            <visual name='visual'>
                <geometry>
                    <cylinder>
                        <length>0.04</length>
                        <radius>0.055</radius>
                    </cylinder>
                </geometry>
                <material>
                    <ambient>0.2 0.2 0.2 1</ambient>
                    <diffuse>0.2 0.2 0.2 1</diffuse>
                    <specular>0.2 0.2 0.2 1</specular>
                </material>
            </visual>
            <collision name='collision'>
                <geometry>
                    <cylinder>
                        <length>0.04</length>
                        <radius>0.055</radius>
                    </cylinder>
                </geometry>
                <surface>
                    <friction>
                        <ode>
                            <mu>0.5</mu>
                            <mu2>1.0</mu2>
                            <fdir1>0 0 1</fdir1>
                        </ode>
                        <bullet>
                            <friction>0.5</friction>
                            <friction2>1</friction2>
                            <rolling_friction>0.5</rolling_friction>
                        </bullet>
                    </friction>
                </surface>
            </collision>
        </link>

        <link name="front_left_wheel_steering_link">
            <pose relative_to="front_left_wheel">-0 0 -0.04 1.570 0 0</pose>
            <inertial>
                <mass>0.5</mass>
                <inertia>
                    <ixx>0.0153</ixx>
                    <iyy>0.025</iyy>
                    <izz>0.0153</izz>
                </inertia>
            </inertial>
            <visual name="steering_link_visual">
                <pose>0 0 0 0 0 0</pose>
                <geometry>
                    <cylinder>
                        <length>0.025</length>
                        <radius>0.015</radius>
                    </cylinder>
                </geometry>
                <material>
                    <ambient>1 1 1</ambient>
                    <diffuse>1 1 1</diffuse>
                </material>
            </visual>
        </link>

        <link name="front_right_wheel_steering_link">
            <pose relative_to="front_right_wheel">-0 0 0.04 1.570 0 0</pose>
            <inertial>
                <mass>0.5</mass>
                <inertia>
                    <ixx>0.0153</ixx>
                    <iyy>0.025</iyy>
                    <izz>0.0153</izz>
                </inertia>
            </inertial>
            <visual name="steering_link_visual">
                <pose>0 0 0 0 0 0</pose>
                <geometry>
                    <cylinder>
                        <length>0.025</length>
                        <radius>0.015</radius>
                    </cylinder>
                </geometry>
                <material>
                    <ambient>1 1 1</ambient>
                    <diffuse>1 1 1</diffuse>
                </material>
            </visual>
        </link>

        <joint name="front_left_wheel_steering_joint" type="revolute">
            <child>front_left_wheel_steering_link</child>
            <parent>chassis</parent>
            <axis>
                <xyz>0 0 1</xyz>
                <limit>
                    <lower>-0.6</lower>
                    <upper>+0.6</upper>
                    <velocity>1.0</velocity>
                    <effort>25</effort>
                </limit>
                <use_parent_model_frame>1</use_parent_model_frame>
            </axis>
        </joint>

        <joint name="front_right_wheel_steering_joint" type="revolute">
            <parent>chassis</parent>
            <child>front_right_wheel_steering_link</child>
            <axis>
                <xyz>0 0 1</xyz>
                <limit>
                    <lower>-0.6</lower>
                    <upper>+0.6</upper>
                    <velocity>1.0</velocity>
                    <effort>25</effort>
                </limit>
            </axis>
        </joint>

        <joint name='front_left_wheel_joint' type='revolute'>
            <parent>front_left_wheel_steering_link</parent>
            <child>front_left_wheel</child>
            <axis>
                <xyz>0 0 1</xyz>
                <limit>
                    <lower>-1.79769e+308</lower>
                    <upper>1.79769e+308</upper>
                </limit>
            </axis>
        </joint>

        <joint name='front_right_wheel_joint' type='revolute'>
            <parent>front_right_wheel_steering_link</parent>
            <child>front_right_wheel</child>
            <axis>
                <xyz>0 0 1</xyz>
                <limit>
                    <lower>-1.79769e+308</lower>
                    <upper>1.79769e+308</upper>
                </limit>
            </axis>
        </joint>

        <joint name='rear_left_wheel_joint' type='revolute'>
            <parent>chassis</parent>
            <child>rear_left_wheel</child>
            <axis>
                <xyz>0 0 1</xyz>
                <limit>
                    <lower>-1.79769e+308</lower>
                    <upper>1.79769e+308</upper>
                </limit>
            </axis>
        </joint>

        <joint name='rear_right_wheel_joint' type='revolute'>
            <parent>chassis</parent>
            <child>rear_right_wheel</child>
            <axis>
                <xyz>0 0 1</xyz>
                <limit>
                    <lower>-1.79769e+308</lower>
                    <upper>1.79769e+308</upper>
                </limit>
            </axis>
        </joint>
        <!-- SENSORS -->
        <link name="camera_link">
            <pose relative_to="lidar_link">0 0 0.05 0 0 0</pose>
            <inertial>
                <mass>0.1</mass>
                <inertia>
                    <ixx>0.000166667</ixx>
                    <iyy>0.000166667</iyy>
                    <izz>0.000166667</izz>
                </inertia>
            </inertial>
            <collision name="collision">
                <geometry>
                    <box>
                        <size>0.05 0.05 0.05</size>
                    </box>
                </geometry>
            </collision>
            <visual name="visual">
                <material>
                    <ambient>0.5 0 0 1</ambient>
                    <diffuse>0.5 0 0 1</diffuse>
                </material>
                <geometry>
                    <box>
                        <size>0.05 0.05 0.05</size>
                    </box>
                </geometry>
            </visual>

            <sensor name="camera" type="camera">
                <camera>
                    <horizontal_fov>1.204277</horizontal_fov>
                    <vertical_fov>0.7330383</vertical_fov>
                    <image>
                        <width>1280</width>
                        <height>720</height>
                    </image>
                    <clip>
                        <near>0.1</near>
                        <far>100</far>
                    </clip>
                </camera>
                <always_on>1</always_on>
                <update_rate>5</update_rate>
                <visualize>true</visualize>
                <topic>camera</topic>
            </sensor>
        <sensor name="depth_camera1" type="depth_camera">
          <update_rate>5</update_rate>
          <topic>depth_camera</topic>
              <camera>
                <horizontal_fov>1.518436</horizontal_fov>
                <vertical_fov>1.012291</vertical_fov>
                <image>
                  <width>1280</width>
                  <height>720</height>
                  <format>R_FLOAT32</format>
                </image>
                <clip>
                  <near>0.28</near>
                  <far>10.0</far>
                </clip>
              </camera>
          </sensor>
        </link>

        <link name="lidar_link">
            <pose relative_to="chassis">0.12 0 0.055 0 0 0</pose>
            <inertial>
                <mass>0.1</mass>
                <inertia>
                    <ixx>0.000166667</ixx>
                    <iyy>0.000166667</iyy>
                    <izz>0.000166667</izz>
                </inertia>
            </inertial>
            <collision name="collision">
                <geometry>
                    <box>
                        <size>0.05 0.05 0.05</size>
                    </box>
                </geometry>
            </collision>
            <visual name="visual">
                <geometry>
                    <box>
                        <size>0.05 0.05 0.05</size>
                    </box>
                </geometry>
            </visual>
            <sensor name='gpu_lidar' type='gpu_lidar'>"
            <topic>scan</topic>
            <update_rate>30</update_rate>
            <lidar>
                <scan>
                    <horizontal>
                        <samples>1081</samples>
                        <resolution>1</resolution>
                        <min_angle>-2.356194</min_angle>
                        <max_angle>2.356194</max_angle>
                    </horizontal>
                    <vertical>
                        <samples>1</samples>
                        <resolution>0.01</resolution>
                        <min_angle>0</min_angle>
                        <max_angle>0</max_angle>
                    </vertical>
                </scan>
                <range>
                    <min>0.06</min>
                    <max>10.0</max>
                    <resolution>0.01</resolution>
                </range>
            </lidar>
            <always_on>1</always_on>
            <visualize>true</visualize>
        </sensor>
    </link>

    <joint name="camera_joint" type="fixed">
        <parent>chassis</parent>
        <child>camera_link</child>
    </joint>
    <joint name="lidar_joint" type="fixed">
        <parent>chassis</parent>
        <child>lidar_link</child>
    </joint>

    <plugin
        filename="gz-sim-ackermann-steering-system"
        name="gz::sim::systems::AckermannSteering">
        <topic>cmd_vel</topic>
        <left_joint>front_left_wheel_joint</left_joint>
        <left_joint>rear_left_wheel_joint</left_joint>
        <right_joint>front_right_wheel_joint</right_joint>
        <right_joint>rear_right_wheel_joint</right_joint>
        <left_steering_joint>front_left_wheel_steering_joint</left_steering_joint>
        <right_steering_joint>front_right_wheel_steering_joint</right_steering_joint>
        <kingpin_width>1.0</kingpin_width>
        <!--steering_limit>0.5</steering_limit-->
        <wheel_base>1.0</wheel_base>
        <wheel_separation>1.25</wheel_separation>
        <wheel_radius>0.3</wheel_radius>
        <!--min_velocity>-1</min_velocity-->
        <!--max_velocity>1</max_velocity-->
        <min_acceleration>-3</min_acceleration>
        <max_acceleration>3</max_acceleration>
    </plugin>
</model>
</sdf>
